Workbook

Sheet 2.5세대
A1: Major | B1: 1 | C1: 2 | D1: 3 | E1: 4 | F1: 5 | G1: 6 | H1: 7 | I1: b2 | J1: b3 | K1: 2M | L1: 3M | M1: 4m | N1: 5m | O1: 6M | P1: b6 | Q1: b7 | R1: Minor | S1: 1 | T1: 2 | U1: 3 | V1: 4 | W1: 5 | X1: 6 | Y1: 7 | Z1: b2 | AA1: 4M | AB1: 5M | AC1: 1M
A2: C | B2: C | C2: Dm | D2: Em | E2: F | F2: G | G2: Am | H2: B | I2: Db | J2: Eb | K2: D | L2: E | M2: Fm | N2: Gm | O2: A | P2: Ab | Q2: Bb | R2: Am | S2: Am | T2: B | U2: C | V2: Dm | W2: Em | X2: F | Y2: G | Z2: Bb | AA2: D | AB2: E | AC2: A
A3: Db | B3: Db | C3: Ebm | D3: Fm | E3: Gb | F3: Ab | G3: Bbm | H3: C | I3: D | J3: Eb | K3: Eb | L3: F | M3: Gbm | N3: Abm | O3: Bb | P3: A | Q3: B | R3: Bbm | S3: Bbm | T3: C | U3: Db | V3: Ebm | W3: Fm | X3: Gb | Y3: Ab | Z3: B | AA3: Eb | AB3: F | AC3: Bb
A4: D | B4: D | C4: Em | D4: F#m | E4: G | F4: A | G4: Bm | H4: C# | I4: Eb | J4: F | K4: E | L4: F# | M4: Gm | N4: Am | O4: B | P4: Bb | Q4: C | R4: Bm | S4: Bm | T4: C# | U4: D | V4: Em | W4: F#m | X4: G | Y4: A | Z4: C | AA4: E | AB4: F# | AC4: B
A5: Eb | B5: Eb | C5: Fm | D5: Gm | E5: Ab | F5: Bb | G5: Cm | H5: D | I5: E | J5: Gb | K5: F | L5: G | M5: Abm | N5: Bbm | O5: C | P5: Cb | Q5: Db | R5: Cm | S5: Cm | T5: D | U5: Eb | V5: Fm | W5: Gm | X5: Ab | Y5: Bb | Z5: Db | AA5: F | AB5: G | AC5: C
A6: E | B6: E | C6: F#m | D6: G#m | E6: A | F6: B | G6: C#m | H6: D# | I6: F | J6: G | K6: F# | L6: G# | M6: Am | N6: Bm | O6: C# | P6: C | Q6: D | R6: C#m | S6: C#m | T6: D# | U6: E | V6: F#m | W6: G#m | X6: A | Y6: B | Z6: D | AA6: F# | AB6: G# | AC6: C#
A7: F | B7: F | C7: Gm | D7: Am | E7: Bb | F7: C | G7: Dm | H7: E | I7: Gb | J7: Ab | K7: G | L7: A | M7: Bbm | N7: Cm | O7: D | P7: Db | Q7: Eb | R7: Dm | S7: Dm | T7: E | U7: F | V7: Gm | W7: Am | X7: Bb | Y7: C | Z7: Eb | AA7: G | AB7: A | AC7: D
A8: Gb | B8: Gb | C8: Abm | D8: Bbm | E8: Cb | F8: Db | G8: Ebm | H8: F | I8: G | J8: A | K8: Ab | L8: Bb | M8: Cbm | N8: Dbm | O8: Eb | P8: D | Q8: E | R8: Ebm | S8: Ebm | T8: F | U8: Gb | V8: Abm | W8: Bbm | X8: Cb | Y8: Db | Z8: E | AA8: G# | AB8: A# | AC8: D#
A9: G | B9: G | C9: Am | D9: Bm | E9: C | F9: D | G9: Em | H9: F# | I9: Ab | J9: Eb | K9: A | L9: B | M9: Cm | N9: Dm | O9: E | P9: Eb | Q9: F | R9: Em | S9: Em | T9: F# | U9: G | V9: Am | W9: Bm | X9: C | Y9: D | Z9: F | AA9: A | AB9: B | AC9: E
A10: Ab | B10: Ab | C10: Bbm | D10: Cm | E10: Db | F10: Eb | G10: Fm | H10: G | I10: A | J10: B | K10: Bb | L10: C | M10: Dbm | N10: Ebm | O10: F | P10: E | Q10: Gb | R10: Fm | S10: Fm | T10: G | U10: Ab | V10: Bbm | W10: Cm | X10: Db | Y10: Eb | Z10: Gb | AA10: Bb | AB10: C | AC10: F
A11: A | B11: A | C11: Bm | D11: C#m | E11: D | F11: E | G11: F#m | H11: G# | I11: Bb | J11: C | K11: B | L11: C# | M11: Dm | N11: Em | O11: F# | P11: F | Q11: G | R11: F#m | S11: F#m | T11: G# | U11: A | V11: Bm | W11: C#m | X11: D | Y11: B | Z11: G | AA11: B | AB11: C# | AC11: F#
A12: Bb | B12: Bb | C12: Cm | D12: Dm | E12: Eb | F12: F | G12: Gm | H12: A | I12: Cb | J12: Db | K12: C | L12: D | M12: Ebm | N12: Fm | O12: G | P12: Gb | Q12: Ab | R12: Gm | S12: Gm | T12: A | U12: Bb | V12: Cm | W12: Dm | X12: Eb | Y12: F | Z12: Ab | AA12: C | AB12: D | AC12: G
A13: B | B13: B | C13: C#m | D13: D#m | E13: E | F13: F# | G13: G#m | H13: A# | I13: Cb | J13: D | K13: C# | L13: D# | M13: Em | N13: F#m | O13: G# | P13: G | Q13: A | R13: G#m | S13: G#m | T13: A# | U13: B | V13: C#m | W13: D#m | X13: E | Y13: F# | Z13: A | AA13: C# | AB13: D# | AC13: G#
A16: 에이핑크 | B16: Mr.Chu (3:25) | C16: intro | K16: verse | S16: pre-chorus | AA16: chorus (키업) | AI16: bridge | AQ16: chorus3 (키업) | AY16: outro
B17: G | C17: A | D17: A | E17: Abm | F17: Dbm | G17: D | H17: D | I17: A | J17: A | K17: A | L17: Abm | M17: A | N17: Abm | O17: A | P17: Abm | Q17: D | R17: Bm | S17: A | T17: Abm | U17: A | V17: Abm | W17: A | X17: Abm | Y17: D | Z17: B | AA17: G | AB17: Bm | AC17: Em | AD17: Dm | AE17: C | AF17: Bm | AG17: Am | AH17: D | AI17: E | AJ17: B | AK17: A | AL17: Bm | AM17: A | AN17: Abm | AO17: F#m | AP17: B | AQ17: G | AR17: Bm | AS17: Em | AT17: Dm | AU17: C | AV17: Bm | AW17: Am | AX17: D | AY17: C | AZ17: Bm | BA17: C | BB17: D | BC17: C | BD17: Bm | BE17: C | BF17: D
B18: 120 | C18: =IFERROR(INDEX('3세대 걸그룹'!$B$1:$Q$1, MATCH(C17, INDEX('3세대 걸그룹'!$B$2:$Q$13, MATCH($B17, '3세대 걸그룹'!$A$2:$A$13, 0), 0), 0)), IFERROR(INDEX('3세대 걸그룹'!$S$1:$AC$1, MATCH(C17, INDEX('3세대 걸그룹'!$S$2:$AC$13, MATCH($B17, '3세대 걸그룹'!$R$2:$R$13, 0), 0), 0)), "")) -> 2M | D18: =IFERROR(INDEX('3세대 걸그룹'!$B$1:$Q$1, MATCH(D17, INDEX('3세대 걸그룹'!$B$2:$Q$13, MATCH($B17, '3세대 걸그룹'!$A$2:$A$13, 0), 0), 0)), IFERROR(INDEX('3세대 걸그룹'!$S$1:$AC$1, MATCH(D17, INDEX('3세대 걸그룹'!$S$2:$AC$13, MATCH($B17, '3세대 걸그룹'!$R$2:$R$13, 0), 0), 0)), "")) -> 2M | E18: =IFERROR(INDEX('3세대 걸그룹'!$B$1:$Q$1, MATCH(E17, INDEX('3세대 걸그룹'!$B$2:$Q$13, MATCH($B17, '3세대 걸그룹'!$A$2:$A$13, 0), 0), 0)), IFERROR(INDEX('3세대 걸그룹'!$S$1:$AC$1, MATCH(E17, INDEX('3세대 걸그룹'!$S$2:$AC$13, MATCH($B17, '3세대 걸그룹'!$R$2:$R$13, 0), 0), 0)), "")) | F18: =IFERROR(INDEX('3세대 걸그룹'!$B$1:$Q$1, MATCH(F17, INDEX('3세대 걸그룹'!$B$2:$Q$13, MATCH($B17, '3세대 걸그룹'!$A$2:$A$13, 0), 0), 0)), IFERROR(INDEX('3세대 걸그룹'!$S$1:$AC$1, MATCH(F17, INDEX('3세대 걸그룹'!$S$2:$AC$13, MATCH($B17, '3세대 걸그룹'!$R$2:$R$13, 0), 0), 0)), "")) | G18: =IFERROR(INDEX('3세대 걸그룹'!$B$1:$Q$1, MATCH(G17, INDEX('3세대 걸그룹'!$B$2:$Q$13, MATCH($B17, '3세대 걸그룹'!$A$2:$A$13, 0), 0), 0)), IFERROR(INDEX('3세대 걸그룹'!$S$1:$AC$1, MATCH(G17, INDEX('3세대 걸그룹'!$S$2:$AC$13, MATCH($B17, '3세대 걸그룹'!$R$2:$R$13, 0), 0), 0)), "")) -> 5 | H18: =IFERROR(INDEX('3세대 걸그룹'!$B$1:$Q$1, MATCH(H17, INDEX('3세대 걸그룹'!$B$2:$Q$13, MATCH($B17, '3세대 걸그룹'!$A$2:$A$13, 0), 0), 0)), IFERROR(INDEX('3세대 걸그룹'!$S$1:$AC$1, MATCH(H17, INDEX('3세대 걸그룹'!$S$2:$AC$13, MATCH($B17, '3세대 걸그룹'!$R$2:$R$13, 0), 0), 0)), "")) -> 5 | I18: =IFERROR(INDEX('3세대 걸그룹'!$B$1:$Q$1, MATCH(I17, INDEX('3세대 걸그룹'!$B$2:$Q$13, MATCH($B17, '3세대 걸그룹'!$A$2:$A$13, 0), 0), 0)), IFERROR(INDEX('3세대 걸그룹'!$S$1:$AC$1, MATCH(I17, INDEX('3세대 걸그룹'!$S$2:$AC$13, MATCH($B17, '3세대 걸그룹'!$R$2:$R$13, 0), 0), 0)), "")) -> 2M | J18: =IFERROR(INDEX('3세대 걸그룹'!$B$1:$Q$1, MATCH(J17, INDEX('3세대 걸그룹'!$B$2:$Q$13, MATCH($B17, '3세대 걸그룹'!$A$2:$A$13, 0), 0), 0)), IFERROR(INDEX('3세대 걸그룹'!$S$1:$AC$1, MATCH(J17, INDEX('3세대 걸그룹'!$S$2:$AC$13, MATCH($B17, '3세대 걸그룹'!$R$2:$R$13, 0), 0), 0)), "")) -> 2M | ... BF18: =IFERROR(INDEX('3세대 걸그룹'!$B$1:$Q$1, MATCH(BF17, INDEX('3세대 걸그룹'!$B$2:$Q$13, MATCH($B17, '3세대 걸그룹'!$A$2:$A$13, 0), 0), 0)), IFERROR(INDEX('3세대 걸그룹'!$S$1:$AC$1, MATCH(BF17, INDEX('3세대 걸그룹'!$S$2:$AC$13, MATCH($B17, '3세대 걸그룹'!$R$2:$R$13, 0), 0), 0)), "")) -> 5
B19: 20140331 | C19: {=_xlfn.SWITCH(C18&"","1","T","3","T","6","T","b3","T","6M","T","1M","T","2","S","4","S","b6","S","b2","S","2M","S","4m","S","4M","S","5","D","7","D","b7","D","3M","D","5m","D","5M","D","") & _xlfn.SWITCH(D18&"","1","T","3","T","6","T","b3","T","6M","T","1M","T","2","S","4","S","b6","S","b2","S","2M","S","4m","S","4M","S","5","D","7","D","b7","D","3M","D","5m","D","5M","D","") & _xlfn.SWITCH(E18&"","1","T","3","T","6","T","b3","T","6M","T","1M","T","2","S","4","S","b6","S","b2","S","2M","S","4m","S","4M","S","5","D","7","D","b7","D","3M","D","5m","D","5M","D","") & _xlfn.SWITCH(F18&"","1","T","3","T","6","T","b3","T","6M","T","1M","T","2","S","4","S","b6","S","b2","S","2M","S","4m","S","4M","S","5","D","7","D","b7","D","3M","D","5m","D","5M","D","") & " " & _xlfn.SWITCH(G18&"","1","T","3","T","6","T","b3","T","6M","T","1M","T","2","S","4","S","b6","S","b2","S","2M","S","4m","S","4M","S","5","D","7","D","b7","D","3M","D","5m","D","5M","D","") & _xlfn.SWITCH(H18&"","1","T","3","T","6","T","b3","T","6M","T","1M","T","2","S","4","S","b6","S","b2","S","2M","S","4m","S","4M","S","5","D","7","D","b7","D","3M","D","5m","D","5M","D","") & _xlfn.SWITCH(I18&"","1","T","3","T","6","T","b3","T","6M","T","1M","T","2","S","4","S","b6","S","b2","S","2M","S","4m","S","4M","S","5","D","7","D","b7","D","3M","D","5m","D","5M","D","") & _xlfn.SWITCH(J18&"","1","T","3","T","6","T","b3","T","6M","T","1M","T","2","S","4","S","b6","S","b2","S","2M","S","4m","S","4M","S","5","D","7","D","b7","D","3M","D","5m","D","5M","D","")} -> SS DDSS | K19: {=_xlfn.SWITCH(K18&"","1","T","3","T","6","T","b3","T","6M","T","1M","T","2","S","4","S","b6","S","b2","S","2M","S","4m","S","4M","S","5","D","7","D","b7","D","3M","D","5m","D","5M","D","") & _xlfn.SWITCH(L18&"","1","T","3","T","6","T","b3","T","6M","T","1M","T","2","S","4","S","b6","S","b2","S","2M","S","4m","S","4M","S","5","D","7","D","b7","D","3M","D","5m","D","5M","D","") & _xlfn.SWITCH(M18&"","1","T","3","T","6","T","b3","T","6M","T","1M","T","2","S","4","S","b6","S","b2","S","2M","S","4m","S","4M","S","5","D","7","D","b7","D","3M","D","5m","D","5M","D","") & _xlfn.SWITCH(N18&"","1","T","3","T","6","T","b3","T","6M","T","1M","T","2","S","4","S","b6","S","b2","S","2M","S","4m","S","4M","S","5","D","7","D","b7","D","3M","D","5m","D","5M","D","") & " " & _xlfn.SWITCH(O18&"","1","T","3","T","6","T","b3","T","6M","T","1M","T","2","S","4","S","b6","S","b2","S","2M","S","4m","S","4M","S","5","D","7","D","b7","D","3M","D","5m","D","5M","D","") & _xlfn.SWITCH(P18&"","1","T","3","T","6","T","b3","T","6M","T","1M","T","2","S","4","S","b6","S","b2","S","2M","S","4m","S","4M","S","5","D","7","D","b7","D","3M","D","5m","D","5M","D","") & _xlfn.SWITCH(Q18&"","1","T","3","T","6","T","b3","T","6M","T","1M","T","2","S","4","S","b6","S","b2","S","2M","S","4m","S","4M","S","5","D","7","D","b7","D","3M","D","5m","D","5M","D","") & _xlfn.SWITCH(R18&"","1","T","3","T","6","T","b3","T","6M","T","1M","T","2","S","4","S","b6","S","b2","S","2M","S","4m","S","4M","S","5","D","7","D","b7","D","3M","D","5m","D","5M","D","")} -> SS SDT | S19: {=_xlfn.SWITCH(S18&"","1","T","3","T","6","T","b3","T","6M","T","1M","T","2","S","4","S","b6","S","b2","S","2M","S","4m","S","4M","S","5","D","7","D","b7","D","3M","D","5m","D","5M","D","") & _xlfn.SWITCH(T18&"","1","T","3","T","6","T","b3","T","6M","T","1M","T","2","S","4","S","b6","S","b2","S","2M","S","4m","S","4M","S","5","D","7","D","b7","D","3M","D","5m","D","5M","D","") & _xlfn.SWITCH(U18&"","1","T","3","T","6","T","b3","T","6M","T","1M","T","2","S","4","S","b6","S","b2","S","2M","S","4m","S","4M","S","5","D","7","D","b7","D","3M","D","5m","D","5M","D","") & _xlfn.SWITCH(V18&"","1","T","3","T","6","T","b3","T","6M","T","1M","T","2","S","4","S","b6","S","b2","S","2M","S","4m","S","4M","S","5","D","7","D","b7","D","3M","D","5m","D","5M","D","") & " " & _xlfn.SWITCH(W18&"","1","T","3","T","6","T","b3","T","6M","T","1M","T","2","S","4","S","b6","S","b2","S","2M","S","4m","S","4M","S","5","D","7","D","b7","D","3M","D","5m","D","5M","D","") & _xlfn.SWITCH(X18&"","1","T","3","T","6","T","b3","T","6M","T","1M","T","2","S","4","S","b6","S","b2","S","2M","S","4m","S","4M","S","5","D","7","D","b7","D","3M","D","5m","D","5M","D","") & _xlfn.SWITCH(Y18&"","1","T","3","T","6","T","b3","T","6M","T","1M","T","2","S","4","S","b6","S","b2","S","2M","S","4m","S","4M","S","5","D","7","D","b7","D","3M","D","5m","D","5M","D","") & _xlfn.SWITCH(Z18&"","1","T","3","T","6","T","b3","T","6M","T","1M","T","2","S","4","S","b6","S","b2","S","2M","S","4m","S","4M","S","5","D","7","D","b7","D","3M","D","5m","D","5M","D","")} -> SS SDD | AA19: {=_xlfn.SWITCH(AA18&"","1","T","3","T","6","T","b3","T","6M","T","1M","T","2","S","4","S","b6","S","b2","S","2M","S","4m","S","4M","S","5","D","7","D","b7","D","3M","D","5m","D","5M","D","") & _xlfn.SWITCH(AB18&"","1","T","3","T","6","T","b3","T","6M","T","1M","T","2","S","4","S","b6","S","b2","S","2M","S","4m","S","4M","S","5","D","7","D","b7","D","3M","D","5m","D","5M","D","") & _xlfn.SWITCH(AC18&"","1","T","3","T","6","T","b3","T","6M","T","1M","T","2","S","4","S","b6","S","b2","S","2M","S","4m","S","4M","S","5","D","7","D","b7","D","3M","D","5m","D","5M","D","") & _xlfn.SWITCH(AD18&"","1","T","3","T","6","T","b3","T","6M","T","1M","T","2","S","4","S","b6","S","b2","S","2M","S","4m","S","4M","S","5","D","7","D","b7","D","3M","D","5m","D","5M","D","") & " " & _xlfn.SWITCH(AE18&"","1","T","3","T","6","T","b3","T","6M","T","1M","T","2","S","4","S","b6","S","b2","S","2M","S","4m","S","4M","S","5","D","7","D","b7","D","3M","D","5m","D","5M","D","") & _xlfn.SWITCH(AF18&"","1","T","3","T","6","T","b3","T","6M","T","1M","T","2","S","4","S","b6","S","b2","S","2M","S","4m","S","4M","S","5","D","7","D","b7","D","3M","D","5m","D","5M","D","") & _xlfn.SWITCH(AG18&"","1","T","3","T","6","T","b3","T","6M","T","1M","T","2","S","4","S","b6","S","b2","S","2M","S","4m","S","4M","S","5","D","7","D","b7","D","3M","D","5m","D","5M","D","") & _xlfn.SWITCH(AH18&"","1","T","3","T","6","T","b3","T","6M","T","1M","T","2","S","4","S","b6","S","b2","S","2M","S","4m","S","4M","S","5","D","7","D","b7","D","3M","D","5m","D","5M","D","")} -> TTTD STSD | AI19: {=_xlfn.SWITCH(AI18&"","1","T","3","T","6","T","b3","T","6M","T","1M","T","2","S","4","S","b6","S","b2","S","2M","S","4m","S","4M","S","5","D","7","D","b7","D","3M","D","5m","D","5M","D","") & _xlfn.SWITCH(AJ18&"","1","T","3","T","6","T","b3","T","6M","T","1M","T","2","S","4","S","b6","S","b2","S","2M","S","4m","S","4M","S","5","D","7","D","b7","D","3M","D","5m","D","5M","D","") & _xlfn.SWITCH(AK18&"","1","T","3","T","6","T","b3","T","6M","T","1M","T","2","S","4","S","b6","S","b2","S","2M","S","4m","S","4M","S","5","D","7","D","b7","D","3M","D","5m","D","5M","D","") & _xlfn.SWITCH(AL18&"","1","T","3","T","6","T","b3","T","6M","T","1M","T","2","S","4","S","b6","S","b2","S","2M","S","4m","S","4M","S","5","D","7","D","b7","D","3M","D","5m","D","5M","D","") & " " & _xlfn.SWITCH(AM18&"","1","T","3","T","6","T","b3","T","6M","T","1M","T","2","S","4","S","b6","S","b2","S","2M","S","4m","S","4M","S","5","D","7","D","b7","D","3M","D","5m","D","5M","D","") & _xlfn.SWITCH(AN18&"","1","T","3","T","6","T","b3","T","6M","T","1M","T","2","S","4","S","b6","S","b2","S","2M","S","4m","S","4M","S","5","D","7","D","b7","D","3M","D","5m","D","5M","D","") & _xlfn.SWITCH(AO18&"","1","T","3","T","6","T","b3","T","6M","T","1M","T","2","S","4","S","b6","S","b2","S","2M","S","4m","S","4M","S","5","D","7","D","b7","D","3M","D","5m","D","5M","D","") & _xlfn.SWITCH(AP18&"","1","T","3","T","6","T","b3","T","6M","T","1M","T","2","S","4","S","b6","S","b2","S","2M","S","4m","S","4M","S","5","D","7","D","b7","D","3M","D","5m","D","5M","D","")} -> TDST SD | AQ19: {=_xlfn.SWITCH(AQ18&"","1","T","3","T","6","T","b3","T","6M","T","1M","T","2","S","4","S","b6","S","b2","S","2M","S","4m","S","4M","S","5","D","7","D","b7","D","3M","D","5m","D","5M","D","") & _xlfn.SWITCH(AR18&"","1","T","3","T","6","T","b3","T","6M","T","1M","T","2","S","4","S","b6","S","b2","S","2M","S","4m","S","4M","S","5","D","7","D","b7","D","3M","D","5m","D","5M","D","") & _xlfn.SWITCH(AS18&"","1","T","3","T","6","T","b3","T","6M","T","1M","T","2","S","4","S","b6","S","b2","S","2M","S","4m","S","4M","S","5","D","7","D","b7","D","3M","D","5m","D","5M","D","") & _xlfn.SWITCH(AT18&"","1","T","3","T","6","T","b3","T","6M","T","1M","T","2","S","4","S","b6","S","b2","S","2M","S","4m","S","4M","S","5","D","7","D","b7","D","3M","D","5m","D","5M","D","") & " " & _xlfn.SWITCH(AU18&"","1","T","3","T","6","T","b3","T","6M","T","1M","T","2","S","4","S","b6","S","b2","S","2M","S","4m","S","4M","S","5","D","7","D","b7","D","3M","D","5m","D","5M","D","") & _xlfn.SWITCH(AV18&"","1","T","3","T","6","T","b3","T","6M","T","1M","T","2","S","4","S","b6","S","b2","S","2M","S","4m","S","4M","S","5","D","7","D","b7","D","3M","D","5m","D","5M","D","") & _xlfn.SWITCH(AW18&"","1","T","3","T","6","T","b3","T","6M","T","1M","T","2","S","4","S","b6","S","b2","S","2M","S","4m","S","4M","S","5","D","7","D","b7","D","3M","D","5m","D","5M","D","") & _xlfn.SWITCH(AX18&"","1","T","3","T","6","T","b3","T","6M","T","1M","T","2","S","4","S","b6","S","b2","S","2M","S","4m","S","4M","S","5","D","7","D","b7","D","3M","D","5m","D","5M","D","")} -> TTTD STSD | AY19: {=_xlfn.SWITCH(AY18&"","1","T","3","T","6","T","b3","T","6M","T","1M","T","2","S","4","S","b6","S","b2","S","2M","S","4m","S","4M","S","5","D","7","D","b7","D","3M","D","5m","D","5M","D","") & _xlfn.SWITCH(AZ18&"","1","T","3","T","6","T","b3","T","6M","T","1M","T","2","S","4","S","b6","S","b2","S","2M","S","4m","S","4M","S","5","D","7","D","b7","D","3M","D","5m","D","5M","D","") & _xlfn.SWITCH(BA18&"","1","T","3","T","6","T","b3","T","6M","T","1M","T","2","S","4","S","b6","S","b2","S","2M","S","4m","S","4M","S","5","D","7","D","b7","D","3M","D","5m","D","5M","D","") & _xlfn.SWITCH(BB18&"","1","T","3","T","6","T","b3","T","6M","T","1M","T","2","S","4","S","b6","S","b2","S","2M","S","4m","S","4M","S","5","D","7","D","b7","D","3M","D","5m","D","5M","D","") & " " & _xlfn.SWITCH(BC18&"","1","T","3","T","6","T","b3","T","6M","T","1M","T","2","S","4","S","b6","S","b2","S","2M","S","4m","S","4M","S","5","D","7","D","b7","D","3M","D","5m","D","5M","D","") & _xlfn.SWITCH(BD18&"","1","T","3","T","6","T","b3","T","6M","T","1M","T","2","S","4","S","b6","S","b2","S","2M","S","4m","S","4M","S","5","D","7","D","b7","D","3M","D","5m","D","5M","D","") & _xlfn.SWITCH(BE18&"","1","T","3","T","6","T","b3","T","6M","T","1M","T","2","S","4","S","b6","S","b2","S","2M","S","4m","S","4M","S","5","D","7","D","b7","D","3M","D","5m","D","5M","D","") & _xlfn.SWITCH(BF18&"","1","T","3","T","6","T","b3","T","6M","T","1M","T","2","S","4","S","b6","S","b2","S","2M","S","4m","S","4M","S","5","D","7","D","b7","D","3M","D","5m","D","5M","D","")} -> STSD STSD
B20: NoNoNo (3:40) | C20: intro | K20: verse | S20: pre-chorus | AA20: chorus-part1 | AI20: chorus-part2 | AQ20: post-chorus1 | AY20: bridge | BG20: chorus3-part1 | BO20: chorus3-part2 | BW20: outro
B21: Em | C21: C | D21: D | E21: Bm | F21: Em | G21: Am | H21: D | I21: Bm | J21: Em | K21: E | L21: B | M21: A | N21: Am | O21: E | P21: F# | Q21: A | R21: B | S21: A | T21: B | U21: G#m | V21: c#m | W21: A | X21: B | Y21: Bm | Z21: E | AA21: C | AB21: D | AC21: Bm | AD21: Em | AE21: C | AF21: D | AG21: Bm | AH21: Em | AI21: Am | AJ21: D | AK21: Bm | AL21: Em | AM21: Am | AN21: Am | AO21: C | AP21: C | AQ21: Em | AR21: Em | AS21: C | AT21: D | AU21: Em | AV21: Em | AW21: C | AX21: D | AY21: C | AZ21: D | BA21: B | BB21: E | BC21: Am | BD21: C | BE21: F | BF21: D | BG21: C | BH21: D | BI21: Bm | BJ21: Em | BK21: C | BL21: D | BM21: Bm | BN21: Em | BO21: Am | BP21: D | BQ21: Bm | BR21: Em | BS21: Am | BT21: Am | BU21: C | BV21: C | BW21: Em | BX21: Em | BY21: C | BZ21: D | CA21: Em | CB21: Em | CC21: C | CD21: D
B22: 106 | C22: =IFERROR(INDEX('3세대 걸그룹'!$B$1:$Q$1, MATCH(C21, INDEX('3세대 걸그룹'!$B$2:$Q$13, MATCH($B21, '3세대 걸그룹'!$A$2:$A$13, 0), 0), 0)), IFERROR(INDEX('3세대 걸그룹'!$S$1:$AC$1, MATCH(C21, INDEX('3세대 걸그룹'!$S$2:$AC$13, MATCH($B21, '3세대 걸그룹'!$R$2:$R$13, 0), 0), 0)), "")) -> 6 | D22: =IFERROR(INDEX('3세대 걸그룹'!$B$1:$Q$1, MATCH(D21, INDEX('3세대 걸그룹'!$B$2:$Q$13, MATCH($B21, '3세대 걸그룹'!$A$2:$A$13, 0), 0), 0)), IFERROR(INDEX('3세대 걸그룹'!$S$1:$AC$1, MATCH(D21, INDEX('3세대 걸그룹'!$S$2:$AC$13, MATCH($B21, '3세대 걸그룹'!$R$2:$R$13, 0), 0), 0)), "")) -> 7 | E22: =IFERROR(INDEX('3세대 걸그룹'!$B$1:$Q$1, MATCH(E21, INDEX('3세대 걸그룹'!$B$2:$Q$13, MATCH($B21, '3세대 걸그룹'!$A$2:$A$13, 0), 0), 0)), IFERROR(INDEX('3세대 걸그룹'!$S$1:$AC$1, MATCH(E21, INDEX('3세대 걸그룹'!$S$2:$AC$13, MATCH($B21, '3세대 걸그룹'!$R$2:$R$13, 0), 0), 0)), "")) -> 5 | F22: =IFERROR(INDEX('3세대 걸그룹'!$B$1:$Q$1, MATCH(F21, INDEX('3세대 걸그룹'!$B$2:$Q$13, MATCH($B21, '3세대 걸그룹'!$A$2:$A$13, 0), 0), 0)), IFERROR(INDEX('3세대 걸그룹'!$S$1:$AC$1, MATCH(F21, INDEX('3세대 걸그룹'!$S$2:$AC$13, MATCH($B21, '3세대 걸그룹'!$R$2:$R$13, 0), 0), 0)), "")) -> 1 | G22: =IFERROR(INDEX('3세대 걸그룹'!$B$1:$Q$1, MATCH(G21, INDEX('3세대 걸그룹'!$B$2:$Q$13, MATCH($B21, '3세대 걸그룹'!$A$2:$A$13, 0), 0), 0)), IFERROR(INDEX('3세대 걸그룹'!$S$1:$AC$1, MATCH(G21, INDEX('3세대 걸그룹'!$S$2:$AC$13, MATCH($B21, '3세대 걸그룹'!$R$2:$R$13, 0), 0), 0)), "")) -> 4 | H22: =IFERROR(INDEX('3세대 걸그룹'!$B$1:$Q$1, MATCH(H21, INDEX('3세대 걸그룹'!$B$2:$Q$13, MATCH($B21, '3세대 걸그룹'!$A$2:$A$13, 0), 0), 0)), IFERROR(INDEX('3세대 걸그룹'!$S$1:$AC$1, MATCH(H21, INDEX('3세대 걸그룹'!$S$2:$AC$13, MATCH($B21, '3세대 걸그룹'!$R$2:$R$13, 0), 0), 0)), "")) -> 7 | I22: =IFERROR(INDEX('3세대 걸그룹'!$B$1:$Q$1, MATCH(I21, INDEX('3세대 걸그룹'!$B$2:$Q$13, MATCH($B21, '3세대 걸그룹'!$A$2:$A$13, 0), 0), 0)), IFERROR(INDEX('3세대 걸그룹'!$S$1:$AC$1, MATCH(I21, INDEX('3세대 걸그룹'!$S$2:$AC$13, MATCH($B21, '3세대 걸그룹'!$R$2:$R$13, 0), 0), 0)), "")) -> 5 | J22: =IFERROR(INDEX('3세대 걸그룹'!$B$1:$Q$1, MATCH(J21, INDEX('3세대 걸그룹'!$B$2:$Q$13, MATCH($B21, '3세대 걸그룹'!$A$2:$A$13, 0), 0), 0)), IFERROR(INDEX('3세대 걸그룹'!$S$1:$AC$1, MATCH(J21, INDEX('3세대 걸그룹'!$S$2:$AC$13, MATCH($B21, '3세대 걸그룹'!$R$2:$R$13, 0), 0), 0)), "")) -> 1 | ... CD22: =IFERROR(INDEX('3세대 걸그룹'!$B$1:$Q$1, MATCH(CD21, INDEX('3세대 걸그룹'!$B$2:$Q$13, MATCH($B21, '3세대 걸그룹'!$A$2:$A$13, 0), 0), 0)), IFERROR(INDEX('3세대 걸그룹'!$S$1:$AC$1, MATCH(CD21, INDEX('3세대 걸그룹'!$S$2:$AC$13, MATCH($B21, '3세대 걸그룹'!$R$2:$R$13, 0), 0), 0)), "")) -> 7
B23: 20130705 | C23: {=_xlfn.SWITCH(C22&"","1","T","3","T","6","T","b3","T","6M","T","1M","T","2","S","4","S","b6","S","b2","S","2M","S","4m","S","4M","S","5","D","7","D","b7","D","3M","D","5m","D","5M","D","") & _xlfn.SWITCH(D22&"","1","T","3","T","6","T","b3","T","6M","T","1M","T","2","S","4","S","b6","S","b2","S","2M","S","4m","S","4M","S","5","D","7","D","b7","D","3M","D","5m","D","5M","D","") & _xlfn.SWITCH(E22&"","1","T","3","T","6","T","b3","T","6M","T","1M","T","2","S","4","S","b6","S","b2","S","2M","S","4m","S","4M","S","5","D","7","D","b7","D","3M","D","5m","D","5M","D","") & _xlfn.SWITCH(F22&"","1","T","3","T","6","T","b3","T","6M","T","1M","T","2","S","4","S","b6","S","b2","S","2M","S","4m","S","4M","S","5","D","7","D","b7","D","3M","D","5m","D","5M","D","") & " " & _xlfn.SWITCH(G22&"","1","T","3","T","6","T","b3","T","6M","T","1M","T","2","S","4","S","b6","S","b2","S","2M","S","4m","S","4M","S","5","D","7","D","b7","D","3M","D","5m","D","5M","D","") & _xlfn.SWITCH(H22&"","1","T","3","T","6","T","b3","T","6M","T","1M","T","2","S","4","S","b6","S","b2","S","2M","S","4m","S","4M","S","5","D","7","D","b7","D","3M","D","5m","D","5M","D","") & _xlfn.SWITCH(I22&"","1","T","3","T","6","T","b3","T","6M","T","1M","T","2","S","4","S","b6","S","b2","S","2M","S","4m","S","4M","S","5","D","7","D","b7","D","3M","D","5m","D","5M","D","") & _xlfn.SWITCH(J22&"","1","T","3","T","6","T","b3","T","6M","T","1M","T","2","S","4","S","b6","S","b2","S","2M","S","4m","S","4M","S","5","D","7","D","b7","D","3M","D","5m","D","5M","D","")} -> TDDT SDDT | K23: {=_xlfn.SWITCH(K22&"","1","T","3","T","6","T","b3","T","6M","T","1M","T","2","S","4","S","b6","S","b2","S","2M","S","4m","S","4M","S","5","D","7","D","b7","D","3M","D","5m","D","5M","D","") & _xlfn.SWITCH(L22&"","1","T","3","T","6","T","b3","T","6M","T","1M","T","2","S","4","S","b6","S","b2","S","2M","S","4m","S","4M","S","5","D","7","D","b7","D","3M","D","5m","D","5M","D","") & _xlfn.SWITCH(M22&"","1","T","3","T","6","T","b3","T","6M","T","1M","T","2","S","4","S","b6","S","b2","S","2M","S","4m","S","4M","S","5","D","7","D","b7","D","3M","D","5m","D","5M","D","") & _xlfn.SWITCH(N22&"","1","T","3","T","6","T","b3","T","6M","T","1M","T","2","S","4","S","b6","S","b2","S","2M","S","4m","S","4M","S","5","D","7","D","b7","D","3M","D","5m","D","5M","D","") & " " & _xlfn.SWITCH(O22&"","1","T","3","T","6","T","b3","T","6M","T","1M","T","2","S","4","S","b6","S","b2","S","2M","S","4m","S","4M","S","5","D","7","D","b7","D","3M","D","5m","D","5M","D","") & _xlfn.SWITCH(P22&"","1","T","3","T","6","T","b3","T","6M","T","1M","T","2","S","4","S","b6","S","b2","S","2M","S","4m","S","4M","S","5","D","7","D","b7","D","3M","D","5m","D","5M","D","") & _xlfn.SWITCH(Q22&"","1","T","3","T","6","T","b3","T","6M","T","1M","T","2","S","4","S","b6","S","b2","S","2M","S","4m","S","4M","S","5","D","7","D","b7","D","3M","D","5m","D","5M","D","") & _xlfn.SWITCH(R22&"","1","T","3","T","6","T","b3","T","6M","T","1M","T","2","S","4","S","b6","S","b2","S","2M","S","4m","S","4M","S","5","D","7","D","b7","D","3M","D","5m","D","5M","D","")} -> TDSS TSSD | S23: {=_xlfn.SWITCH(S22&"","1","T","3","T","6","T","b3","T","6M","T","1M","T","2","S","4","S","b6","S","b2","S","2M","S","4m","S","4M","S","5","D","7","D","b7","D","3M","D","5m","D","5M","D","") & _xlfn.SWITCH(T22&"","1","T","3","T","6","T","b3","T","6M","T","1M","T","2","S","4","S","b6","S","b2","S","2M","S","4m","S","4M","S","5","D","7","D","b7","D","3M","D","5m","D","5M","D","") & _xlfn.SWITCH(U22&"","1","T","3","T","6","T","b3","T","6M","T","1M","T","2","S","4","S","b6","S","b2","S","2M","S","4m","S","4M","S","5","D","7","D","b7","D","3M","D","5m","D","5M","D","") & _xlfn.SWITCH(V22&"","1","T","3","T","6","T","b3","T","6M","T","1M","T","2","S","4","S","b6","S","b2","S","2M","S","4m","S","4M","S","5","D","7","D","b7","D","3M","D","5m","D","5M","D","") & " " & _xlfn.SWITCH(W22&"","1","T","3","T","6","T","b3","T","6M","T","1M","T","2","S","4","S","b6","S","b2","S","2M","S","4m","S","4M","S","5","D","7","D","b7","D","3M","D","5m","D","5M","D","") & _xlfn.SWITCH(X22&"","1","T","3","T","6","T","b3","T","6M","T","1M","T","2","S","4","S","b6","S","b2","S","2M","S","4m","S","4M","S","5","D","7","D","b7","D","3M","D","5m","D","5M","D","") & _xlfn.SWITCH(Y22&"","1","T","3","T","6","T","b3","T","6M","T","1M","T","2","S","4","S","b6","S","b2","S","2M","S","4m","S","4M","S","5","D","7","D","b7","D","3M","D","5m","D","5M","D","") & _xlfn.SWITCH(Z22&"","1","T","3","T","6","T","b3","T","6M","T","1M","T","2","S","4","S","b6","S","b2","S","2M","S","4m","S","4M","S","5","D","7","D","b7","D","3M","D","5m","D","5M","D","")} -> SD SDDT | AA23: {=_xlfn.SWITCH(AA22&"","1","T","3","T","6","T","b3","T","6M","T","1M","T","2","S","4","S","b6","S","b2","S","2M","S","4m","S","4M","S","5","D","7","D","b7","D","3M","D","5m","D","5M","D","") & _xlfn.SWITCH(AB22&"","1","T","3","T","6","T","b3","T","6M","T","1M","T","2","S","4","S","b6","S","b2","S","2M","S","4m","S","4M","S","5","D","7","D","b7","D","3M","D","5m","D","5M","D","") & _xlfn.SWITCH(AC22&"","1","T","3","T","6","T","b3","T","6M","T","1M","T","2","S","4","S","b6","S","b2","S","2M","S","4m","S","4M","S","5","D","7","D","b7","D","3M","D","5m","D","5M","D","") & _xlfn.SWITCH(AD22&"","1","T","3","T","6","T","b3","T","6M","T","1M","T","2","S","4","S","b6","S","b2","S","2M","S","4m","S","4M","S","5","D","7","D","b7","D","3M","D","5m","D","5M","D","") & " " & _xlfn.SWITCH(AE22&"","1","T","3","T","6","T","b3","T","6M","T","1M","T","2","S","4","S","b6","S","b2","S","2M","S","4m","S","4M","S","5","D","7","D","b7","D","3M","D","5m","D","5M","D","") & _xlfn.SWITCH(AF22&"","1","T","3","T","6","T","b3","T","6M","T","1M","T","2","S","4","S","b6","S","b2","S","2M","S","4m","S","4M","S","5","D","7","D","b7","D","3M","D","5m","D","5M","D","") & _xlfn.SWITCH(AG22&"","1","T","3","T","6","T","b3","T","6M","T","1M","T","2","S","4","S","b6","S","b2","S","2M","S","4m","S","4M","S","5","D","7","D","b7","D","3M","D","5m","D","5M","D","") & _xlfn.SWITCH(AH22&"","1","T","3","T","6","T","b3","T","6M","T","1M","T","2","S","4","S","b6","S","b2","S","2M","S","4m","S","4M","S","5","D","7","D","b7","D","3M","D","5m","D","5M","D","")} -> TDDT TDDT | AI23: {=_xlfn.SWITCH(AI22&"","1","T","3","T","6","T","b3","T","6M","T","1M","T","2","S","4","S","b6","S","b2","S","2M","S","4m","S","4M","S","5","D","7","D","b7","D","3M","D","5m","D","5M","D","") & _xlfn.SWITCH(AJ22&"","1","T","3","T","6","T","b3","T","6M","T","1M","T","2","S","4","S","b6","S","b2","S","2M","S","4m","S","4M","S","5","D","7","D","b7","D","3M","D","5m","D","5M","D","") & _xlfn.SWITCH(AK22&"","1","T","3","T","6","T","b3","T","6M","T","1M","T","2","S","4","S","b6","S","b2","S","2M","S","4m","S","4M","S","5","D","7","D","b7","D","3M","D","5m","D","5M","D","") & _xlfn.SWITCH(AL22&"","1","T","3","T","6","T","b3","T","6M","T","1M","T","2","S","4","S","b6","S","b2","S","2M","S","4m","S","4M","S","5","D","7","D","b7","D","3M","D","5m","D","5M","D","") & " " & _xlfn.SWITCH(AM22&"","1","T","3","T","6","T","b3","T","6M","T","1M","T","2","S","4","S","b6","S","b2","S","2M","S","4m","S","4M","S","5","D","7","D","b7","D","3M","D","5m","D","5M","D","") & _xlfn.SWITCH(AN22&"","1","T","3","T","6","T","b3","T","6M","T","1M","T","2","S","4","S","b6","S","b2","S","2M","S","4m","S","4M","S","5","D","7","D","b7","D","3M","D","5m","D","5M","D","") & _xlfn.SWITCH(AO22&"","1","T","3","T","6","T","b3","T","6M","T","1M","T","2","S","4","S","b6","S","b2","S","2M","S","4m","S","4M","S","5","D","7","D","b7","D","3M","D","5m","D","5M","D","") & _xlfn.SWITCH(AP22&"","1","T","3","T","6","T","b3","T","6M","T","1M","T","2","S","4","S","b6","S","b2","S","2M","S","4m","S","4M","S","5","D","7","D","b7","D","3M","D","5m","D","5M","D","")} -> SDDT SSTT | AQ23: {=_xlfn.SWITCH(AQ22&"","1","T","3","T","6","T","b3","T","6M","T","1M","T","2","S","4","S","b6","S","b2","S","2M","S","4m","S","4M","S","5","D","7","D","b7","D","3M","D","5m","D","5M","D","") & _xlfn.SWITCH(AR22&"","1","T","3","T","6","T","b3","T","6M","T","1M","T","2","S","4","S","b6","S","b2","S","2M","S","4m","S","4M","S","5","D","7","D","b7","D","3M","D","5m","D","5M","D","") & _xlfn.SWITCH(AS22&"","1","T","3","T","6","T","b3","T","6M","T","1M","T","2","S","4","S","b6","S","b2","S","2M","S","4m","S","4M","S","5","D","7","D","b7","D","3M","D","5m","D","5M","D","") & _xlfn.SWITCH(AT22&"","1","T","3","T","6","T","b3","T","6M","T","1M","T","2","S","4","S","b6","S","b2","S","2M","S","4m","S","4M","S","5","D","7","D","b7","D","3M","D","5m","D","5M","D","") & " " & _xlfn.SWITCH(AU22&"","1","T","3","T","6","T","b3","T","6M","T","1M","T","2","S","4","S","b6","S","b2","S","2M","S","4m","S","4M","S","5","D","7","D","b7","D","3M","D","5m","D","5M","D","") & _xlfn.SWITCH(AV22&"","1","T","3","T","6","T","b3","T","6M","T","1M","T","2","S","4","S","b6","S","b2","S","2M","S","4m","S","4M","S","5","D","7","D","b7","D","3M","D","5m","D","5M","D","") & _xlfn.SWITCH(AW22&"","1","T","3","T","6","T","b3","T","6M","T","1M","T","2","S","4","S","b6","S","b2","S","2M","S","4m","S","4M","S","5","D","7","D","b7","D","3M","D","5m","D","5M","D","") & _xlfn.SWITCH(AX22&"","1","T","3","T","6","T","b3","T","6M","T","1M","T","2","S","4","S","b6","S","b2","S","2M","S","4m","S","4M","S","5","D","7","D","b7","D","3M","D","5m","D","5M","D","")} -> TTTD TTTD | AY23: {=_xlfn.SWITCH(AY22&"","1","T","3","T","6","T","b3","T","6M","T","1M","T","2","S","4","S","b6","S","b2","S","2M","S","4m","S","4M","S","5","D","7","D","b7","D","3M","D","5m","D","5M","D","") & _xlfn.SWITCH(AZ22&"","1","T","3","T","6","T","b3","T","6M","T","1M","T","2","S","4","S","b6","S","b2","S","2M","S","4m","S","4M","S","5","D","7","D","b7","D","3M","D","5m","D","5M","D","") & _xlfn.SWITCH(BA22&"","1","T","3","T","6","T","b3","T","6M","T","1M","T","2","S","4","S","b6","S","b2","S","2M","S","4m","S","4M","S","5","D","7","D","b7","D","3M","D","5m","D","5M","D","") & _xlfn.SWITCH(BB22&"","1","T","3","T","6","T","b3","T","6M","T","1M","T","2","S","4","S","b6","S","b2","S","2M","S","4m","S","4M","S","5","D","7","D","b7","D","3M","D","5m","D","5M","D","") & " " & _xlfn.SWITCH(BC22&"","1","T","3","T","6","T","b3","T","6M","T","1M","T","2","S","4","S","b6","S","b2","S","2M","S","4m","S","4M","S","5","D","7","D","b7","D","3M","D","5m","D","5M","D","") & _xlfn.SWITCH(BD22&"","1","T","3","T","6","T","b3","T","6M","T","1M","T","2","S","4","S","b6","S","b2","S","2M","S","4m","S","4M","S","5","D","7","D","b7","D","3M","D","5m","D","5M","D","") & _xlfn.SWITCH(BE22&"","1","T","3","T","6","T","b3","T","6M","T","1M","T","2","S","4","S","b6","S","b2","S","2M","S","4m","S","4M","S","5","D","7","D","b7","D","3M","D","5m","D","5M","D","") & _xlfn.SWITCH(BF22&"","1","T","3","T","6","T","b3","T","6M","T","1M","T","2","S","4","S","b6","S","b2","S","2M","S","4m","S","4M","S","5","D","7","D","b7","D","3M","D","5m","D","5M","D","")} -> TDDT STSD | BG23: {=_xlfn.SWITCH(BG22&"","1","T","3","T","6","T","b3","T","6M","T","1M","T","2","S","4","S","b6","S","b2","S","2M","S","4m","S","4M","S","5","D","7","D","b7","D","3M","D","5m","D","5M","D","") & _xlfn.SWITCH(BH22&"","1","T","3","T","6","T","b3","T","6M","T","1M","T","2","S","4","S","b6","S","b2","S","2M","S","4m","S","4M","S","5","D","7","D","b7","D","3M","D","5m","D","5M","D","") & _xlfn.SWITCH(BI22&"","1","T","3","T","6","T","b3","T","6M","T","1M","T","2","S","4","S","b6","S","b2","S","2M","S","4m","S","4M","S","5","D","7","D","b7","D","3M","D","5m","D","5M","D","") & _xlfn.SWITCH(BJ22&"","1","T","3","T","6","T","b3","T","6M","T","1M","T","2","S","4","S","b6","S","b2","S","2M","S","4m","S","4M","S","5","D","7","D","b7","D","3M","D","5m","D","5M","D","") & " " & _xlfn.SWITCH(BK22&"","1","T","3","T","6","T","b3","T","6M","T","1M","T","2","S","4","S","b6","S","b2","S","2M","S","4m","S","4M","S","5","D","7","D","b7","D","3M","D","5m","D","5M","D","") & _xlfn.SWITCH(BL22&"","1","T","3","T","6","T","b3","T","6M","T","1M","T","2","S","4","S","b6","S","b2","S","2M","S","4m","S","4M","S","5","D","7","D","b7","D","3M","D","5m","D","5M","D","") & _xlfn.SWITCH(BM22&"","1","T","3","T","6","T","b3","T","6M","T","1M","T","2","S","4","S","b6","S","b2","S","2M","S","4m","S","4M","S","5","D","7","D","b7","D","3M","D","5m","D","5M","D","") & _xlfn.SWITCH(BN22&"","1","T","3","T","6","T","b3","T","6M","T","1M","T","2","S","4","S","b6","S","b2","S","2M","S","4m","S","4M","S","5","D","7","D","b7","D","3M","D","5m","D","5M","D","")} -> TDDT TDDT | BO23: {=_xlfn.SWITCH(BO22&"","1","T","3","T","6","T","b3","T","6M","T","1M","T","2","S","4","S","b6","S","b2","S","2M","S","4m","S","4M","S","5","D","7","D","b7","D","3M","D","5m","D","5M","D","") & _xlfn.SWITCH(BP22&"","1","T","3","T","6","T","b3","T","6M","T","1M","T","2","S","4","S","b6","S","b2","S","2M","S","4m","S","4M","S","5","D","7","D","b7","D","3M","D","5m","D","5M","D","") & _xlfn.SWITCH(BQ22&"","1","T","3","T","6","T","b3","T","6M","T","1M","T","2","S","4","S","b6","S","b2","S","2M","S","4m","S","4M","S","5","D","7","D","b7","D","3M","D","5m","D","5M","D","") & _xlfn.SWITCH(BR22&"","1","T","3","T","6","T","b3","T","6M","T","1M","T","2","S","4","S","b6","S","b2","S","2M","S","4m","S","4M","S","5","D","7","D","b7","D","3M","D","5m","D","5M","D","") & " " & _xlfn.SWITCH(BS22&"","1","T","3","T","6","T","b3","T","6M","T","1M","T","2","S","4","S","b6","S","b2","S","2M","S","4m","S","4M","S","5","D","7","D","b7","D","3M","D","5m","D","5M","D","") & _xlfn.SWITCH(BT22&"","1","T","3","T","6","T","b3","T","6M","T","1M","T","2","S","4","S","b6","S","b2","S","2M","S","4m","S","4M","S","5","D","7","D","b7","D","3M","D","5m","D","5M","D","") & _xlfn.SWITCH(BU22&"","1","T","3","T","6","T","b3","T","6M","T","1M","T","2","S","4","S","b6","S","b2","S","2M","S","4m","S","4M","S","5","D","7","D","b7","D","3M","D","5m","D","5M","D","") & _xlfn.SWITCH(BV22&"","1","T","3","T","6","T","b3","T","6M","T","1M","T","2","S","4","S","b6","S","b2","S","2M","S","4m","S","4M","S","5","D","7","D","b7","D","3M","D","5m","D","5M","D","")} -> SDDT SSTT | BW23: {=_xlfn.SWITCH(BW22&"","1","T","3","T","6","T","b3","T","6M","T","1M","T","2","S","4","S","b6","S","b2","S","2M","S","4m","S","4M","S","5","D","7","D","b7","D","3M","D","5m","D","5M","D","") & _xlfn.SWITCH(BX22&"","1","T","3","T","6","T","b3","T","6M","T","1M","T","2","S","4","S","b6","S","b2","S","2M","S","4m","S","4M","S","5","D","7","D","b7","D","3M","D","5m","D","5M","D","") & _xlfn.SWITCH(BY22&"","1","T","3","T","6","T","b3","T","6M","T","1M","T","2","S","4","S","b6","S","b2","S","2M","S","4m","S","4M","S","5","D","7","D","b7","D","3M","D","5m","D","5M","D","") & _xlfn.SWITCH(BZ22&"","1","T","3","T","6","T","b3","T","6M","T","1M","T","2","S","4","S","b6","S","b2","S","2M","S","4m","S","4M","S","5","D","7","D","b7","D","3M","D","5m","D","5M","D","") & " " & _xlfn.SWITCH(CA22&"","1","T","3","T","6","T","b3","T","6M","T","1M","T","2","S","4","S","b6","S","b2","S","2M","S","4m","S","4M","S","5","D","7","D","b7","D","3M","D","5m","D","5M","D","") & _xlfn.SWITCH(CB22&"","1","T","3","T","6","T","b3","T","6M","T","1M","T","2","S","4","S","b6","S","b2","S","2M","S","4m","S","4M","S","5","D","7","D","b7","D","3M","D","5m","D","5M","D","") & _xlfn.SWITCH(CC22&"","1","T","3","T","6","T","b3","T","6M","T","1M","T","2","S","4","S","b6","S","b2","S","2M","S","4m","S","4M","S","5","D","7","D","b7","D","3M","D","5m","D","5M","D","") & _xlfn.SWITCH(CD22&"","1","T","3","T","6","T","b3","T","6M","T","1M","T","2","S","4","S","b6","S","b2","S","2M","S","4m","S","4M","S","5","D","7","D","b7","D","3M","D","5m","D","5M","D","")} -> TTTD TTTD
B24: Remember (3:52) | C24: intro | K24: verse | S24: pre-chorus | AA24: chorus-part1 | AI24: chorus-part2 (2키업) | AQ24: bridge | AY24: dance-brake (2키업) | BG24: chorus-part2 (3키업)
B25: Gb | C25: Db | D25: Eb | E25: Cm | F25: Fm | G25: Bbm | H25: Ab | I25: Db | J25: Ebm | K25: Gb | L25: Ebm | M25: Abm | N25: Db | O25: Bbm | P25: Gm | Q25: Abm | R25: Db | S25: Abm | T25: Gb | U25: Cb | V25: Gb | W25: Abm | X25: Gb | Y25: Cbm | Z25: Db | AA25: Cb | AB25: Db | AC25: bbm | AD25: Ebm | AI25: Db | AJ25: Eb | AK25: Cm | AL25: Fm | AM25: Bbm | AN25: Ab | AO25: Db | AP25: Eb | AQ25: Fb | AR25: Gb | AS25: G | AT25: Abm | AU25: Dbm | AV25: Cb | AW25: Db | AX25: Gb | AY25: Db | AZ25: Eb | BA25: Cm | BB25: Fm | BC25: Bbm | BD25: Ab | BE25: Db | BF25: Eb | BG25: D | BH25: Fb | BI25: Dbm | BJ25: Gbm | BK25: Cbm | BL25: A | BM25: D | BN25: Fb
B26: 120 | C26: =IFERROR(INDEX('3세대 걸그룹'!$B$1:$Q$1, MATCH(C25, INDEX('3세대 걸그룹'!$B$2:$Q$13, MATCH($B25, '3세대 걸그룹'!$A$2:$A$13, 0), 0), 0)), IFERROR(INDEX('3세대 걸그룹'!$S$1:$AC$1, MATCH(C25, INDEX('3세대 걸그룹'!$S$2:$AC$13, MATCH($B25, '3세대 걸그룹'!$R$2:$R$13, 0), 0), 0)), "")) -> 5 | D26: =IFERROR(INDEX('3세대 걸그룹'!$B$1:$Q$1, MATCH(D25, INDEX('3세대 걸그룹'!$B$2:$Q$13, MATCH($B25, '3세대 걸그룹'!$A$2:$A$13, 0), 0), 0)), IFERROR(INDEX('3세대 걸그룹'!$S$1:$AC$1, MATCH(D25, INDEX('3세대 걸그룹'!$S$2:$AC$13, MATCH($B25, '3세대 걸그룹'!$R$2:$R$13, 0), 0), 0)), "")) -> 6M | E26: =IFERROR(INDEX('3세대 걸그룹'!$B$1:$Q$1, MATCH(E25, INDEX('3세대 걸그룹'!$B$2:$Q$13, MATCH($B25, '3세대 걸그룹'!$A$2:$A$13, 0), 0), 0)), IFERROR(INDEX('3세대 걸그룹'!$S$1:$AC$1, MATCH(E25, INDEX('3세대 걸그룹'!$S$2:$AC$13, MATCH($B25, '3세대 걸그룹'!$R$2:$R$13, 0), 0), 0)), "")) | F26: =IFERROR(INDEX('3세대 걸그룹'!$B$1:$Q$1, MATCH(F25, INDEX('3세대 걸그룹'!$B$2:$Q$13, MATCH($B25, '3세대 걸그룹'!$A$2:$A$13, 0), 0), 0)), IFERROR(INDEX('3세대 걸그룹'!$S$1:$AC$1, MATCH(F25, INDEX('3세대 걸그룹'!$S$2:$AC$13, MATCH($B25, '3세대 걸그룹'!$R$2:$R$13, 0), 0), 0)), "")) | G26: =IFERROR(INDEX('3세대 걸그룹'!$B$1:$Q$1, MATCH(G25, INDEX('3세대 걸그룹'!$B$2:$Q$13, MATCH($B25, '3세대 걸그룹'!$A$2:$A$13, 0), 0), 0)), IFERROR(INDEX('3세대 걸그룹'!$S$1:$AC$1, MATCH(G25, INDEX('3세대 걸그룹'!$S$2:$AC$13, MATCH($B25, '3세대 걸그룹'!$R$2:$R$13, 0), 0), 0)), "")) -> 3 | H26: =IFERROR(INDEX('3세대 걸그룹'!$B$1:$Q$1, MATCH(H25, INDEX('3세대 걸그룹'!$B$2:$Q$13, MATCH($B25, '3세대 걸그룹'!$A$2:$A$13, 0), 0), 0)), IFERROR(INDEX('3세대 걸그룹'!$S$1:$AC$1, MATCH(H25, INDEX('3세대 걸그룹'!$S$2:$AC$13, MATCH($B25, '3세대 걸그룹'!$R$2:$R$13, 0), 0), 0)), "")) -> 2M | I26: =IFERROR(INDEX('3세대 걸그룹'!$B$1:$Q$1, MATCH(I25, INDEX('3세대 걸그룹'!$B$2:$Q$13, MATCH($B25, '3세대 걸그룹'!$A$2:$A$13, 0), 0), 0)), IFERROR(INDEX('3세대 걸그룹'!$S$1:$AC$1, MATCH(I25, INDEX('3세대 걸그룹'!$S$2:$AC$13, MATCH($B25, '3세대 걸그룹'!$R$2:$R$13, 0), 0), 0)), "")) -> 5 | J26: =IFERROR(INDEX('3세대 걸그룹'!$B$1:$Q$1, MATCH(J25, INDEX('3세대 걸그룹'!$B$2:$Q$13, MATCH($B25, '3세대 걸그룹'!$A$2:$A$13, 0), 0), 0)), IFERROR(INDEX('3세대 걸그룹'!$S$1:$AC$1, MATCH(J25, INDEX('3세대 걸그룹'!$S$2:$AC$13, MATCH($B25, '3세대 걸그룹'!$R$2:$R$13, 0), 0), 0)), "")) -> 6 | ... BN26: =IFERROR(INDEX('3세대 걸그룹'!$B$1:$Q$1, MATCH(BN25, INDEX('3세대 걸그룹'!$B$2:$Q$13, MATCH($B25, '3세대 걸그룹'!$A$2:$A$13, 0), 0), 0)), IFERROR(INDEX('3세대 걸그룹'!$S$1:$AC$1, MATCH(BN25, INDEX('3세대 걸그룹'!$S$2:$AC$13, MATCH($B25, '3세대 걸그룹'!$R$2:$R$13, 0), 0), 0)), ""))
B27: 20150716 | C27: {=_xlfn.SWITCH(C26&"","1","T","3","T","6","T","b3","T","6M","T","1M","T","2","S","4","S","b6","S","b2","S","2M","S","4m","S","4M","S","5","D","7","D","b7","D","3M","D","5m","D","5M","D","") & _xlfn.SWITCH(D26&"","1","T","3","T","6","T","b3","T","6M","T","1M","T","2","S","4","S","b6","S","b2","S","2M","S","4m","S","4M","S","5","D","7","D","b7","D","3M","D","5m","D","5M","D","") & _xlfn.SWITCH(E26&"","1","T","3","T","6","T","b3","T","6M","T","1M","T","2","S","4","S","b6","S","b2","S","2M","S","4m","S","4M","S","5","D","7","D","b7","D","3M","D","5m","D","5M","D","") & _xlfn.SWITCH(F26&"","1","T","3","T","6","T","b3","T","6M","T","1M","T","2","S","4","S","b6","S","b2","S","2M","S","4m","S","4M","S","5","D","7","D","b7","D","3M","D","5m","D","5M","D","") & " " & _xlfn.SWITCH(G26&"","1","T","3","T","6","T","b3","T","6M","T","1M","T","2","S","4","S","b6","S","b2","S","2M","S","4m","S","4M","S","5","D","7","D","b7","D","3M","D","5m","D","5M","D","") & _xlfn.SWITCH(H26&"","1","T","3","T","6","T","b3","T","6M","T","1M","T","2","S","4","S","b6","S","b2","S","2M","S","4m","S","4M","S","5","D","7","D","b7","D","3M","D","5m","D","5M","D","") & _xlfn.SWITCH(I26&"","1","T","3","T","6","T","b3","T","6M","T","1M","T","2","S","4","S","b6","S","b2","S","2M","S","4m","S","4M","S","5","D","7","D","b7","D","3M","D","5m","D","5M","D","") & _xlfn.SWITCH(J26&"","1","T","3","T","6","T","b3","T","6M","T","1M","T","2","S","4","S","b6","S","b2","S","2M","S","4m","S","4M","S","5","D","7","D","b7","D","3M","D","5m","D","5M","D","")} -> DT TSDT | K27: {=_xlfn.SWITCH(K26&"","1","T","3","T","6","T","b3","T","6M","T","1M","T","2","S","4","S","b6","S","b2","S","2M","S","4m","S","4M","S","5","D","7","D","b7","D","3M","D","5m","D","5M","D","") & _xlfn.SWITCH(L26&"","1","T","3","T","6","T","b3","T","6M","T","1M","T","2","S","4","S","b6","S","b2","S","2M","S","4m","S","4M","S","5","D","7","D","b7","D","3M","D","5m","D","5M","D","") & _xlfn.SWITCH(M26&"","1","T","3","T","6","T","b3","T","6M","T","1M","T","2","S","4","S","b6","S","b2","S","2M","S","4m","S","4M","S","5","D","7","D","b7","D","3M","D","5m","D","5M","D","") & _xlfn.SWITCH(N26&"","1","T","3","T","6","T","b3","T","6M","T","1M","T","2","S","4","S","b6","S","b2","S","2M","S","4m","S","4M","S","5","D","7","D","b7","D","3M","D","5m","D","5M","D","") & " " & _xlfn.SWITCH(O26&"","1","T","3","T","6","T","b3","T","6M","T","1M","T","2","S","4","S","b6","S","b2","S","2M","S","4m","S","4M","S","5","D","7","D","b7","D","3M","D","5m","D","5M","D","") & _xlfn.SWITCH(P26&"","1","T","3","T","6","T","b3","T","6M","T","1M","T","2","S","4","S","b6","S","b2","S","2M","S","4m","S","4M","S","5","D","7","D","b7","D","3M","D","5m","D","5M","D","") & _xlfn.SWITCH(Q26&"","1","T","3","T","6","T","b3","T","6M","T","1M","T","2","S","4","S","b6","S","b2","S","2M","S","4m","S","4M","S","5","D","7","D","b7","D","3M","D","5m","D","5M","D","") & _xlfn.SWITCH(R26&"","1","T","3","T","6","T","b3","T","6M","T","1M","T","2","S","4","S","b6","S","b2","S","2M","S","4m","S","4M","S","5","D","7","D","b7","D","3M","D","5m","D","5M","D","")} -> TTSD TSD | S27: {=_xlfn.SWITCH(S26&"","1","T","3","T","6","T","b3","T","6M","T","1M","T","2","S","4","S","b6","S","b2","S","2M","S","4m","S","4M","S","5","D","7","D","b7","D","3M","D","5m","D","5M","D","") & _xlfn.SWITCH(T26&"","1","T","3","T","6","T","b3","T","6M","T","1M","T","2","S","4","S","b6","S","b2","S","2M","S","4m","S","4M","S","5","D","7","D","b7","D","3M","D","5m","D","5M","D","") & _xlfn.SWITCH(U26&"","1","T","3","T","6","T","b3","T","6M","T","1M","T","2","S","4","S","b6","S","b2","S","2M","S","4m","S","4M","S","5","D","7","D","b7","D","3M","D","5m","D","5M","D","") & _xlfn.SWITCH(V26&"","1","T","3","T","6","T","b3","T","6M","T","1M","T","2","S","4","S","b6","S","b2","S","2M","S","4m","S","4M","S","5","D","7","D","b7","D","3M","D","5m","D","5M","D","") & " " & _xlfn.SWITCH(W26&"","1","T","3","T","6","T","b3","T","6M","T","1M","T","2","S","4","S","b6","S","b2","S","2M","S","4m","S","4M","S","5","D","7","D","b7","D","3M","D","5m","D","5M","D","") & _xlfn.SWITCH(X26&"","1","T","3","T","6","T","b3","T","6M","T","1M","T","2","S","4","S","b6","S","b2","S","2M","S","4m","S","4M","S","5","D","7","D","b7","D","3M","D","5m","D","5M","D","") & _xlfn.SWITCH(Y26&"","1","T","3","T","6","T","b3","T","6M","T","1M","T","2","S","4","S","b6","S","b2","S","2M","S","4m","S","4M","S","5","D","7","D","b7","D","3M","D","5m","D","5M","D","") & _xlfn.SWITCH(Z26&"","1","T","3","T","6","T","b3","T","6M","T","1M","T","2","S","4","S","b6","S","b2","S","2M","S","4m","S","4M","S","5","D","7","D","b7","D","3M","D","5m","D","5M","D","")} -> STST STSD | AA27: {=_xlfn.SWITCH(AA26&"","1","T","3","T","6","T","b3","T","6M","T","1M","T","2","S","4","S","b6","S","b2","S","2M","S","4m","S","4M","S","5","D","7","D","b7","D","3M","D","5m","D","5M","D","") & _xlfn.SWITCH(AB26&"","1","T","3","T","6","T","b3","T","6M","T","1M","T","2","S","4","S","b6","S","b2","S","2M","S","4m","S","4M","S","5","D","7","D","b7","D","3M","D","5m","D","5M","D","") & _xlfn.SWITCH(AC26&"","1","T","3","T","6","T","b3","T","6M","T","1M","T","2","S","4","S","b6","S","b2","S","2M","S","4m","S","4M","S","5","D","7","D","b7","D","3M","D","5m","D","5M","D","") & _xlfn.SWITCH(AD26&"","1","T","3","T","6","T","b3","T","6M","T","1M","T","2","S","4","S","b6","S","b2","S","2M","S","4m","S","4M","S","5","D","7","D","b7","D","3M","D","5m","D","5M","D","") & " " & _xlfn.SWITCH(AE26&"","1","T","3","T","6","T","b3","T","6M","T","1M","T","2","S","4","S","b6","S","b2","S","2M","S","4m","S","4M","S","5","D","7","D","b7","D","3M","D","5m","D","5M","D","") & _xlfn.SWITCH(AF26&"","1","T","3","T","6","T","b3","T","6M","T","1M","T","2","S","4","S","b6","S","b2","S","2M","S","4m","S","4M","S","5","D","7","D","b7","D","3M","D","5m","D","5M","D","") & _xlfn.SWITCH(AG26&"","1","T","3","T","6","T","b3","T","6M","T","1M","T","2","S","4","S","b6","S","b2","S","2M","S","4m","S","4M","S","5","D","7","D","b7","D","3M","D","5m","D","5M","D","") & _xlfn.SWITCH(AH26&"","1","T","3","T","6","T","b3","T","6M","T","1M","T","2","S","4","S","b6","S","b2","S","2M","S","4m","S","4M","S","5","D","7","D","b7","D","3M","D","5m","D","5M","D","")} -> SDTT | AI27: {=_xlfn.SWITCH(AI26&"","1","T","3","T","6","T","b3","T","6M","T","1M","T","2","S","4","S","b6","S","b2","S","2M","S","4m","S","4M","S","5","D","7","D","b7","D","3M","D","5m","D","5M","D","") & _xlfn.SWITCH(AJ26&"","1","T","3","T","6","T","b3","T","6M","T","1M","T","2","S","4","S","b6","S","b2","S","2M","S","4m","S","4M","S","5","D","7","D","b7","D","3M","D","5m","D","5M","D","") & _xlfn.SWITCH(AK26&"","1","T","3","T","6","T","b3","T","6M","T","1M","T","2","S","4","S","b6","S","b2","S","2M","S","4m","S","4M","S","5","D","7","D","b7","D","3M","D","5m","D","5M","D","") & _xlfn.SWITCH(AL26&"","1","T","3","T","6","T","b3","T","6M","T","1M","T","2","S","4","S","b6","S","b2","S","2M","S","4m","S","4M","S","5","D","7","D","b7","D","3M","D","5m","D","5M","D","") & " " & _xlfn.SWITCH(AM26&"","1","T","3","T","6","T","b3","T","6M","T","1M","T","2","S","4","S","b6","S","b2","S","2M","S","4m","S","4M","S","5","D","7","D","b7","D","3M","D","5m","D","5M","D","") & _xlfn.SWITCH(AN26&"","1","T","3","T","6","T","b3","T","6M","T","1M","T","2","S","4","S","b6","S","b2","S","2M","S","4m","S","4M","S","5","D","7","D","b7","D","3M","D","5m","D","5M","D","") & _xlfn.SWITCH(AO26&"","1","T","3","T","6","T","b3","T","6M","T","1M","T","2","S","4","S","b6","S","b2","S","2M","S","4m","S","4M","S","5","D","7","D","b7","D","3M","D","5m","D","5M","D","") & _xlfn.SWITCH(AP26&"","1","T","3","T","6","T","b3","T","6M","T","1M","T","2","S","4","S","b6","S","b2","S","2M","S","4m","S","4M","S","5","D","7","D","b7","D","3M","D","5m","D","5M","D","")} -> DT TSDT | AQ27: {=_xlfn.SWITCH(AQ26&"","1","T","3","T","6","T","b3","T","6M","T","1M","T","2","S","4","S","b6","S","b2","S","2M","S","4m","S","4M","S","5","D","7","D","b7","D","3M","D","5m","D","5M","D","") & _xlfn.SWITCH(AR26&"","1","T","3","T","6","T","b3","T","6M","T","1M","T","2","S","4","S","b6","S","b2","S","2M","S","4m","S","4M","S","5","D","7","D","b7","D","3M","D","5m","D","5M","D","") & _xlfn.SWITCH(AS26&"","1","T","3","T","6","T","b3","T","6M","T","1M","T","2","S","4","S","b6","S","b2","S","2M","S","4m","S","4M","S","5","D","7","D","b7","D","3M","D","5m","D","5M","D","") & _xlfn.SWITCH(AT26&"","1","T","3","T","6","T","b3","T","6M","T","1M","T","2","S","4","S","b6","S","b2","S","2M","S","4m","S","4M","S","5","D","7","D","b7","D","3M","D","5m","D","5M","D","") & " " & _xlfn.SWITCH(AU26&"","1","T","3","T","6","T","b3","T","6M","T","1M","T","2","S","4","S","b6","S","b2","S","2M","S","4m","S","4M","S","5","D","7","D","b7","D","3M","D","5m","D","5M","D","") & _xlfn.SWITCH(AV26&"","1","T","3","T","6","T","b3","T","6M","T","1M","T","2","S","4","S","b6","S","b2","S","2M","S","4m","S","4M","S","5","D","7","D","b7","D","3M","D","5m","D","5M","D","") & _xlfn.SWITCH(AW26&"","1","T","3","T","6","T","b3","T","6M","T","1M","T","2","S","4","S","b6","S","b2","S","2M","S","4m","S","4M","S","5","D","7","D","b7","D","3M","D","5m","D","5M","D","") & _xlfn.SWITCH(AX26&"","1","T","3","T","6","T","b3","T","6M","T","1M","T","2","S","4","S","b6","S","b2","S","2M","S","4m","S","4M","S","5","D","7","D","b7","D","3M","D","5m","D","5M","D","")} -> TSS DSDT | AY27: {=_xlfn.SWITCH(AY26&"","1","T","3","T","6","T","b3","T","6M","T","1M","T","2","S","4","S","b6","S","b2","S","2M","S","4m","S","4M","S","5","D","7","D","b7","D","3M","D","5m","D","5M","D","") & _xlfn.SWITCH(AZ26&"","1","T","3","T","6","T","b3","T","6M","T","1M","T","2","S","4","S","b6","S","b2","S","2M","S","4m","S","4M","S","5","D","7","D","b7","D","3M","D","5m","D","5M","D","") & _xlfn.SWITCH(BA26&"","1","T","3","T","6","T","b3","T","6M","T","1M","T","2","S","4","S","b6","S","b2","S","2M","S","4m","S","4M","S","5","D","7","D","b7","D","3M","D","5m","D","5M","D","") & _xlfn.SWITCH(BB26&"","1","T","3","T","6","T","b3","T","6M","T","1M","T","2","S","4","S","b6","S","b2","S","2M","S","4m","S","4M","S","5","D","7","D","b7","D","3M","D","5m","D","5M","D","") & " " & _xlfn.SWITCH(BC26&"","1","T","3","T","6","T","b3","T","6M","T","1M","T","2","S","4","S","b6","S","b2","S","2M","S","4m","S","4M","S","5","D","7","D","b7","D","3M","D","5m","D","5M","D","") & _xlfn.SWITCH(BD26&"","1","T","3","T","6","T","b3","T","6M","T","1M","T","2","S","4","S","b6","S","b2","S","2M","S","4m","S","4M","S","5","D","7","D","b7","D","3M","D","5m","D","5M","D","") & _xlfn.SWITCH(BE26&"","1","T","3","T","6","T","b3","T","6M","T","1M","T","2","S","4","S","b6","S","b2","S","2M","S","4m","S","4M","S","5","D","7","D","b7","D","3M","D","5m","D","5M","D","") & _xlfn.SWITCH(BF26&"","1","T","3","T","6","T","b3","T","6M","T","1M","T","2","S","4","S","b6","S","b2","S","2M","S","4m","S","4M","S","5","D","7","D","b7","D","3M","D","5m","D","5M","D","")} -> DT TSDT | BG27: {=_xlfn.SWITCH(BG26&"","1","T","3","T","6","T","b3","T","6M","T","1M","T","2","S","4","S","b6","S","b2","S","2M","S","4m","S","4M","S","5","D","7","D","b7","D","3M","D","5m","D","5M","D","") & _xlfn.SWITCH(BH26&"","1","T","3","T","6","T","b3","T","6M","T","1M","T","2","S","4","S","b6","S","b2","S","2M","S","4m","S","4M","S","5","D","7","D","b7","D","3M","D","5m","D","5M","D","") & _xlfn.SWITCH(BI26&"","1","T","3","T","6","T","b3","T","6M","T","1M","T","2","S","4","S","b6","S","b2","S","2M","S","4m","S","4M","S","5","D","7","D","b7","D","3M","D","5m","D","5M","D","") & _xlfn.SWITCH(BJ26&"","1","T","3","T","6","T","b3","T","6M","T","1M","T","2","S","4","S","b6","S","b2","S","2M","S","4m","S","4M","S","5","D","7","D","b7","D","3M","D","5m","D","5M","D","") & " " & _xlfn.SWITCH(BK26&"","1","T","3","T","6","T","b3","T","6M","T","1M","T","2","S","4","S","b6","S","b2","S","2M","S","4m","S","4M","S","5","D","7","D","b7","D","3M","D","5m","D","5M","D","") & _xlfn.SWITCH(BL26&"","1","T","3","T","6","T","b3","T","6M","T","1M","T","2","S","4","S","b6","S","b2","S","2M","S","4m","S","4M","S","5","D","7","D","b7","D","3M","D","5m","D","5M","D","") & _xlfn.SWITCH(BM26&"","1","T","3","T","6","T","b3","T","6M","T","1M","T","2","S","4","S","b6","S","b2","S","2M","S","4m","S","4M","S","5","D","7","D","b7","D","3M","D","5m","D","5M","D","") & _xlfn.SWITCH(BN26&"","1","T","3","T","6","T","b3","T","6M","T","1M","T","2","S","4","S","b6","S","b2","S","2M","S","4m","S","4M","S","5","D","7","D","b7","D","3M","D","5m","D","5M","D","")} -> SD STS
B28: LUV (3:58) | C28: intro | K28: verse | S28: pre-chorus | AA28: chorus | AI28: bridge | AQ28: chorus3
B29: F#m | C29: D | D29: E | E29: C#m | F29: F#m | G29: D | H29: E | I29: C#m | J29: F#m | K29: D | L29: E | M29: C#m | N29: F#m | O29: D | P29: E | Q29: C#m | R29: F#m | S29: Bm | T29: C#m | U29: D | V29: E | W29: Bm | X29: C#m | Y29: E# | Z29: A | AA29: D | AB29: E | AC29: C#m | AD29: F#m | AE29: D | AF29: E | AG29: C#m | AH29: F#m | AI29: Bm | AJ29: A | AK29: D | AL29: A | AM29: D | AN29: F#m | AO29: G | AP29: A | AQ29: D | AR29: E | AS29: C#m | AT29: F#m | AU29: D | AV29: E | AW29: C#m | AX29: F#m
B30: 104 | C30: =IFERROR(INDEX('3세대 걸그룹'!$B$1:$Q$1, MATCH(C29, INDEX('3세대 걸그룹'!$B$2:$Q$13, MATCH($B29, '3세대 걸그룹'!$A$2:$A$13, 0), 0), 0)), IFERROR(INDEX('3세대 걸그룹'!$S$1:$AC$1, MATCH(C29, INDEX('3세대 걸그룹'!$S$2:$AC$13, MATCH($B29, '3세대 걸그룹'!$R$2:$R$13, 0), 0), 0)), "")) -> 6 | D30: =IFERROR(INDEX('3세대 걸그룹'!$B$1:$Q$1, MATCH(D29, INDEX('3세대 걸그룹'!$B$2:$Q$13, MATCH($B29, '3세대 걸그룹'!$A$2:$A$13, 0), 0), 0)), IFERROR(INDEX('3세대 걸그룹'!$S$1:$AC$1, MATCH(D29, INDEX('3세대 걸그룹'!$S$2:$AC$13, MATCH($B29, '3세대 걸그룹'!$R$2:$R$13, 0), 0), 0)), "")) | E30: =IFERROR(INDEX('3세대 걸그룹'!$B$1:$Q$1, MATCH(E29, INDEX('3세대 걸그룹'!$B$2:$Q$13, MATCH($B29, '3세대 걸그룹'!$A$2:$A$13, 0), 0), 0)), IFERROR(INDEX('3세대 걸그룹'!$S$1:$AC$1, MATCH(E29, INDEX('3세대 걸그룹'!$S$2:$AC$13, MATCH($B29, '3세대 걸그룹'!$R$2:$R$13, 0), 0), 0)), "")) -> 5 | F30: =IFERROR(INDEX('3세대 걸그룹'!$B$1:$Q$1, MATCH(F29, INDEX('3세대 걸그룹'!$B$2:$Q$13, MATCH($B29, '3세대 걸그룹'!$A$2:$A$13, 0), 0), 0)), IFERROR(INDEX('3세대 걸그룹'!$S$1:$AC$1, MATCH(F29, INDEX('3세대 걸그룹'!$S$2:$AC$13, MATCH($B29, '3세대 걸그룹'!$R$2:$R$13, 0), 0), 0)), "")) -> 1 | G30: =IFERROR(INDEX('3세대 걸그룹'!$B$1:$Q$1, MATCH(G29, INDEX('3세대 걸그룹'!$B$2:$Q$13, MATCH($B29, '3세대 걸그룹'!$A$2:$A$13, 0), 0), 0)), IFERROR(INDEX('3세대 걸그룹'!$S$1:$AC$1, MATCH(G29, INDEX('3세대 걸그룹'!$S$2:$AC$13, MATCH($B29, '3세대 걸그룹'!$R$2:$R$13, 0), 0), 0)), "")) -> 6 | H30: =IFERROR(INDEX('3세대 걸그룹'!$B$1:$Q$1, MATCH(H29, INDEX('3세대 걸그룹'!$B$2:$Q$13, MATCH($B29, '3세대 걸그룹'!$A$2:$A$13, 0), 0), 0)), IFERROR(INDEX('3세대 걸그룹'!$S$1:$AC$1, MATCH(H29, INDEX('3세대 걸그룹'!$S$2:$AC$13, MATCH($B29, '3세대 걸그룹'!$R$2:$R$13, 0), 0), 0)), "")) | I30: =IFERROR(INDEX('3세대 걸그룹'!$B$1:$Q$1, MATCH(I29, INDEX('3세대 걸그룹'!$B$2:$Q$13, MATCH($B29, '3세대 걸그룹'!$A$2:$A$13, 0), 0), 0)), IFERROR(INDEX('3세대 걸그룹'!$S$1:$AC$1, MATCH(I29, INDEX('3세대 걸그룹'!$S$2:$AC$13, MATCH($B29, '3세대 걸그룹'!$R$2:$R$13, 0), 0), 0)), "")) -> 5 | J30: =IFERROR(INDEX('3세대 걸그룹'!$B$1:$Q$1, MATCH(J29, INDEX('3세대 걸그룹'!$B$2:$Q$13, MATCH($B29, '3세대 걸그룹'!$A$2:$A$13, 0), 0), 0)), IFERROR(INDEX('3세대 걸그룹'!$S$1:$AC$1, MATCH(J29, INDEX('3세대 걸그룹'!$S$2:$AC$13, MATCH($B29, '3세대 걸그룹'!$R$2:$R$13, 0), 0), 0)), "")) -> 1 | ... AX30: =IFERROR(INDEX('3세대 걸그룹'!$B$1:$Q$1, MATCH(AX29, INDEX('3세대 걸그룹'!$B$2:$Q$13, MATCH($B29, '3세대 걸그룹'!$A$2:$A$13, 0), 0), 0)), IFERROR(INDEX('3세대 걸그룹'!$S$1:$AC$1, MATCH(AX29, INDEX('3세대 걸그룹'!$S$2:$AC$13, MATCH($B29, '3세대 걸그룹'!$R$2:$R$13, 0), 0), 0)), "")) -> 1
